{"type": "LOG", "log": {"level": "INFO", "message": "Starting syncing SourceFreshcaller"}}
{"type": "LOG", "log": {"level": "FATAL", "message": "1 validation error for AirbyteStateBlob\n__root__\n  AirbyteStateBlob expected dict not str (type=type_error)\nTraceback (most recent call last):\n  File \"pydantic/main.py\", line 522, in pydantic.main.BaseModel.parse_obj\nValueError: dictionary update sequence element #0 has length 1; 2 is required\n\nThe above exception was the direct cause of the following exception:\n\nTraceback (most recent call last):\n  File \"/airbyte/integration_code/main.py\", line 13, in <module>\n    launch(source, sys.argv[1:])\n  File \"/usr/local/lib/python3.9/site-packages/airbyte_cdk/entrypoint.py\", line 209, in launch\n    for message in source_entrypoint.run(parsed_args):\n  File \"/usr/local/lib/python3.9/site-packages/airbyte_cdk/entrypoint.py\", line 116, in run\n    yield from map(AirbyteEntrypoint.airbyte_message_to_string, self.read(source_spec, config, config_catalog, state))\n  File \"/usr/local/lib/python3.9/site-packages/airbyte_cdk/entrypoint.py\", line 158, in read\n    yield from self.source.read(self.logger, config, catalog, state)\n  File \"/usr/local/lib/python3.9/site-packages/airbyte_cdk/sources/declarative/manifest_declarative_source.py\", line 138, in read\n    yield from super().read(logger, config, catalog, state)\n  File \"/usr/local/lib/python3.9/site-packages/airbyte_cdk/sources/abstract_source.py\", line 100, in read\n    state_manager = ConnectorStateManager(stream_instance_map=stream_instances, state=state)\n  File \"/usr/local/lib/python3.9/site-packages/airbyte_cdk/sources/connector_state_manager.py\", line 34, in __init__\n    shared_state, per_stream_states = self._extract_from_state_message(state, stream_instance_map)\n  File \"/usr/local/lib/python3.9/site-packages/airbyte_cdk/sources/connector_state_manager.py\", line 124, in _extract_from_state_message\n    streams = cls._create_descriptor_to_stream_state_mapping(state[0].data, stream_instance_map)  # type: ignore # We verified that state is a list in _is_migrated_legacy_state\n  File \"/usr/local/lib/python3.9/site-packages/airbyte_cdk/sources/connector_state_manager.py\", line 164, in _create_descriptor_to_stream_state_mapping\n    streams[stream_descriptor] = AirbyteStateBlob.parse_obj(state_value or {})\n  File \"pydantic/main.py\", line 525, in pydantic.main.BaseModel.parse_obj\npydantic.error_wrappers.ValidationError: 1 validation error for AirbyteStateBlob\n__root__\n  AirbyteStateBlob expected dict not str (type=type_error)"}}
{"type": "TRACE", "trace": {"type": "ERROR", "emitted_at": 1699293426444.6199, "error": {"message": "Something went wrong in the connector. See the logs for more details.", "internal_message": "1 validation error for AirbyteStateBlob\n__root__\n  AirbyteStateBlob expected dict not str (type=type_error)", "stack_trace": "Traceback (most recent call last):\n  File \"pydantic/main.py\", line 522, in pydantic.main.BaseModel.parse_obj\nValueError: dictionary update sequence element #0 has length 1; 2 is required\n\nThe above exception was the direct cause of the following exception:\n\nTraceback (most recent call last):\n  File \"/airbyte/integration_code/main.py\", line 13, in <module>\n    launch(source, sys.argv[1:])\n  File \"/usr/local/lib/python3.9/site-packages/airbyte_cdk/entrypoint.py\", line 209, in launch\n    for message in source_entrypoint.run(parsed_args):\n  File \"/usr/local/lib/python3.9/site-packages/airbyte_cdk/entrypoint.py\", line 116, in run\n    yield from map(AirbyteEntrypoint.airbyte_message_to_string, self.read(source_spec, config, config_catalog, state))\n  File \"/usr/local/lib/python3.9/site-packages/airbyte_cdk/entrypoint.py\", line 158, in read\n    yield from self.source.read(self.logger, config, catalog, state)\n  File \"/usr/local/lib/python3.9/site-packages/airbyte_cdk/sources/declarative/manifest_declarative_source.py\", line 138, in read\n    yield from super().read(logger, config, catalog, state)\n  File \"/usr/local/lib/python3.9/site-packages/airbyte_cdk/sources/abstract_source.py\", line 100, in read\n    state_manager = ConnectorStateManager(stream_instance_map=stream_instances, state=state)\n  File \"/usr/local/lib/python3.9/site-packages/airbyte_cdk/sources/connector_state_manager.py\", line 34, in __init__\n    shared_state, per_stream_states = self._extract_from_state_message(state, stream_instance_map)\n  File \"/usr/local/lib/python3.9/site-packages/airbyte_cdk/sources/connector_state_manager.py\", line 124, in _extract_from_state_message\n    streams = cls._create_descriptor_to_stream_state_mapping(state[0].data, stream_instance_map)  # type: ignore # We verified that state is a list in _is_migrated_legacy_state\n  File \"/usr/local/lib/python3.9/site-packages/airbyte_cdk/sources/connector_state_manager.py\", line 164, in _create_descriptor_to_stream_state_mapping\n    streams[stream_descriptor] = AirbyteStateBlob.parse_obj(state_value or {})\n  File \"pydantic/main.py\", line 525, in pydantic.main.BaseModel.parse_obj\npydantic.error_wrappers.ValidationError: 1 validation error for AirbyteStateBlob\n__root__\n  AirbyteStateBlob expected dict not str (type=type_error)\n", "failure_type": "system_error"}}}
